Workbook

Sheet IRP
A1: Índice de Relación de Pareja (IRP) — versión mejorada
A2: Autovaloración exploratoria: no es una prueba validada, no mide el valor de una persona, no predice el futuro de la relación y no dice qué decidir. Elegí «No sé» si algo no lo conocés.
A4: Tipo | B4: Ítem | C4: Respuesta | D4: Peso | E4: Puntos (0–100) | F4: Aviso | G4: Peso usado | H4: Aporte | I4: Marca | K4: Resultado
A5: Bueno | B5: Paz | C5: No sé | D5: 1 | E5: =IF(OR(C5="",C5="No sé"),"",IF($A5="Bueno",(MATCH(C5,Datos!$A$2:$A$6,0)-1)*25,100-(MATCH(C5,Datos!$A$2:$A$6,0)-1)*25)) | F5: =IF(OR(C5="",C5="No sé"),"",IF(AND(I5="Seguridad",MATCH(C5,Datos!$A$2:$A$6,0)>=2),"ALERTA DE SEGURIDAD",IF(AND(I5="Atención",MATCH(C5,Datos!$A$2:$A$6,0)>=4),"Atención",""))) | G5: =IF(OR(E5="",D5<=0),"",D5) | H5: =IF(G5="","",G5*E5) | K5: Presencia de lo positivo (0–100) | L5: =IFERROR(SUMIFS(H5:H55,A5:A55,"Bueno")/SUMIFS(G5:G55,A5:A55,"Bueno"),"")
A6: Bueno | B6: Sinceridad | C6: No sé | D6: 1 | E6: =IF(OR(C6="",C6="No sé"),"",IF($A6="Bueno",(MATCH(C6,Datos!$A$2:$A$6,0)-1)*25,100-(MATCH(C6,Datos!$A$2:$A$6,0)-1)*25)) | F6: =IF(OR(C6="",C6="No sé"),"",IF(AND(I6="Seguridad",MATCH(C6,Datos!$A$2:$A$6,0)>=2),"ALERTA DE SEGURIDAD",IF(AND(I6="Atención",MATCH(C6,Datos!$A$2:$A$6,0)>=4),"Atención",""))) | G6: =IF(OR(E6="",D6<=0),"",D6) | H6: =IF(G6="","",G6*E6) | K6: Ausencia de lo problemático (0–100) | L6: =IFERROR(SUMIFS(H5:H55,A5:A55,"Malo")/SUMIFS(G5:G55,A5:A55,"Malo"),"")
A7: Bueno | B7: Crecimiento | C7: No sé | D7: 1 | E7: =IF(OR(C7="",C7="No sé"),"",IF($A7="Bueno",(MATCH(C7,Datos!$A$2:$A$6,0)-1)*25,100-(MATCH(C7,Datos!$A$2:$A$6,0)-1)*25)) | F7: =IF(OR(C7="",C7="No sé"),"",IF(AND(I7="Seguridad",MATCH(C7,Datos!$A$2:$A$6,0)>=2),"ALERTA DE SEGURIDAD",IF(AND(I7="Atención",MATCH(C7,Datos!$A$2:$A$6,0)>=4),"Atención",""))) | G7: =IF(OR(E7="",D7<=0),"",D7) | H7: =IF(G7="","",G7*E7) | K7: IRP mejorado (0–100; sin cifra si hay alerta de seguridad) | L7: =IF(L10>0,"—",IF(AND(COUNTIFS(A5:A55,"Bueno",G5:G55,">=0")>=13,COUNTIFS(A5:A55,"Malo",G5:G55,">=0")>=12.5,ISNUMBER(L5),ISNUMBER(L6)),(L5+L6)/2,""))
A8: Bueno | B8: Autoconfianza | C8: No sé | D8: 1 | E8: =IF(OR(C8="",C8="No sé"),"",IF($A8="Bueno",(MATCH(C8,Datos!$A$2:$A$6,0)-1)*25,100-(MATCH(C8,Datos!$A$2:$A$6,0)-1)*25)) | F8: =IF(OR(C8="",C8="No sé"),"",IF(AND(I8="Seguridad",MATCH(C8,Datos!$A$2:$A$6,0)>=2),"ALERTA DE SEGURIDAD",IF(AND(I8="Atención",MATCH(C8,Datos!$A$2:$A$6,0)>=4),"Atención",""))) | G8: =IF(OR(E8="",D8<=0),"",D8) | H8: =IF(G8="","",G8*E8) | K8: Casillas respondidas | L8: =COUNT(G5:G55)&" / 51" -> 0 / 51
A9: Bueno | B9: Metas claras | C9: No sé | D9: 1 | E9: =IF(OR(C9="",C9="No sé"),"",IF($A9="Bueno",(MATCH(C9,Datos!$A$2:$A$6,0)-1)*25,100-(MATCH(C9,Datos!$A$2:$A$6,0)-1)*25)) | F9: =IF(OR(C9="",C9="No sé"),"",IF(AND(I9="Seguridad",MATCH(C9,Datos!$A$2:$A$6,0)>=2),"ALERTA DE SEGURIDAD",IF(AND(I9="Atención",MATCH(C9,Datos!$A$2:$A$6,0)>=4),"Atención",""))) | G9: =IF(OR(E9="",D9<=0),"",D9) | H9: =IF(G9="","",G9*E9) | K9: Cobertura | L9: =COUNT(G5:G55)/51 -> 0
A10: Bueno | B10: Buena influencia | C10: No sé | D10: 1 | E10: =IF(OR(C10="",C10="No sé"),"",IF($A10="Bueno",(MATCH(C10,Datos!$A$2:$A$6,0)-1)*25,100-(MATCH(C10,Datos!$A$2:$A$6,0)-1)*25)) | F10: =IF(OR(C10="",C10="No sé"),"",IF(AND(I10="Seguridad",MATCH(C10,Datos!$A$2:$A$6,0)>=2),"ALERTA DE SEGURIDAD",IF(AND(I10="Atención",MATCH(C10,Datos!$A$2:$A$6,0)>=4),"Atención",""))) | G10: =IF(OR(E10="",D10<=0),"",D10) | H10: =IF(G10="","",G10*E10) | K10: Alertas de seguridad | L10: =COUNTIF(F5:F55,"ALERTA DE SEGURIDAD") -> 0
A11: Bueno | B11: Independiente | C11: No sé | D11: 1 | E11: =IF(OR(C11="",C11="No sé"),"",IF($A11="Bueno",(MATCH(C11,Datos!$A$2:$A$6,0)-1)*25,100-(MATCH(C11,Datos!$A$2:$A$6,0)-1)*25)) | F11: =IF(OR(C11="",C11="No sé"),"",IF(AND(I11="Seguridad",MATCH(C11,Datos!$A$2:$A$6,0)>=2),"ALERTA DE SEGURIDAD",IF(AND(I11="Atención",MATCH(C11,Datos!$A$2:$A$6,0)>=4),"Atención",""))) | G11: =IF(OR(E11="",D11<=0),"",D11) | H11: =IF(G11="","",G11*E11) | K11: Avisos de atención | L11: =COUNTIF(F5:F55,"Atención") -> 0
A12: Bueno | B12: Alegría | C12: No sé | D12: 1 | E12: =IF(OR(C12="",C12="No sé"),"",IF($A12="Bueno",(MATCH(C12,Datos!$A$2:$A$6,0)-1)*25,100-(MATCH(C12,Datos!$A$2:$A$6,0)-1)*25)) | F12: =IF(OR(C12="",C12="No sé"),"",IF(AND(I12="Seguridad",MATCH(C12,Datos!$A$2:$A$6,0)>=2),"ALERTA DE SEGURIDAD",IF(AND(I12="Atención",MATCH(C12,Datos!$A$2:$A$6,0)>=4),"Atención",""))) | G12: =IF(OR(E12="",D12<=0),"",D12) | H12: =IF(G12="","",G12*E12) | K12: Lectura | L12: =IF(L7="","Respondé al menos la mitad de cada lista para ver el índice.",IF(L10>0,"Hay una alerta de seguridad: el promedio no se interpreta (ver aviso abajo).",IF(L7>=85,"Predominan los aspectos positivos en tus respuestas.",IF(L7>=70,"Mayormente positivo, con algunos aspectos a mejorar.",IF(L7>=55,"Panorama mixto: conviven aspectos positivos y problemáticos.",IF(L7>=40,"Predominan los aspectos problemáticos en tus respuestas.","Tus respuestas señalan muchos aspectos problemáticos.")))))) -> Respondé al menos la mitad de cada lista para ver el índice.
A13: Bueno | B13: Placer | C13: No sé | D13: 1 | E13: =IF(OR(C13="",C13="No sé"),"",IF($A13="Bueno",(MATCH(C13,Datos!$A$2:$A$6,0)-1)*25,100-(MATCH(C13,Datos!$A$2:$A$6,0)-1)*25)) | F13: =IF(OR(C13="",C13="No sé"),"",IF(AND(I13="Seguridad",MATCH(C13,Datos!$A$2:$A$6,0)>=2),"ALERTA DE SEGURIDAD",IF(AND(I13="Atención",MATCH(C13,Datos!$A$2:$A$6,0)>=4),"Atención",""))) | G13: =IF(OR(E13="",D13<=0),"",D13) | H13: =IF(G13="","",G13*E13)
A14: Bueno | B14: Ser uno mismo | C14: No sé | D14: 1 | E14: =IF(OR(C14="",C14="No sé"),"",IF($A14="Bueno",(MATCH(C14,Datos!$A$2:$A$6,0)-1)*25,100-(MATCH(C14,Datos!$A$2:$A$6,0)-1)*25)) | F14: =IF(OR(C14="",C14="No sé"),"",IF(AND(I14="Seguridad",MATCH(C14,Datos!$A$2:$A$6,0)>=2),"ALERTA DE SEGURIDAD",IF(AND(I14="Atención",MATCH(C14,Datos!$A$2:$A$6,0)>=4),"Atención",""))) | G14: =IF(OR(E14="",D14<=0),"",D14) | H14: =IF(G14="","",G14*E14)
A15: Bueno | B15: Te ayuda | C15: No sé | D15: 1 | E15: =IF(OR(C15="",C15="No sé"),"",IF($A15="Bueno",(MATCH(C15,Datos!$A$2:$A$6,0)-1)*25,100-(MATCH(C15,Datos!$A$2:$A$6,0)-1)*25)) | F15: =IF(OR(C15="",C15="No sé"),"",IF(AND(I15="Seguridad",MATCH(C15,Datos!$A$2:$A$6,0)>=2),"ALERTA DE SEGURIDAD",IF(AND(I15="Atención",MATCH(C15,Datos!$A$2:$A$6,0)>=4),"Atención",""))) | G15: =IF(OR(E15="",D15<=0),"",D15) | H15: =IF(G15="","",G15*E15)
A16: Bueno | B16: Comprensión | C16: No sé | D16: 1 | E16: =IF(OR(C16="",C16="No sé"),"",IF($A16="Bueno",(MATCH(C16,Datos!$A$2:$A$6,0)-1)*25,100-(MATCH(C16,Datos!$A$2:$A$6,0)-1)*25)) | F16: =IF(OR(C16="",C16="No sé"),"",IF(AND(I16="Seguridad",MATCH(C16,Datos!$A$2:$A$6,0)>=2),"ALERTA DE SEGURIDAD",IF(AND(I16="Atención",MATCH(C16,Datos!$A$2:$A$6,0)>=4),"Atención",""))) | G16: =IF(OR(E16="",D16<=0),"",D16) | H16: =IF(G16="","",G16*E16)
A17: Bueno | B17: Fidelidad | C17: No sé | D17: 1 | E17: =IF(OR(C17="",C17="No sé"),"",IF($A17="Bueno",(MATCH(C17,Datos!$A$2:$A$6,0)-1)*25,100-(MATCH(C17,Datos!$A$2:$A$6,0)-1)*25)) | F17: =IF(OR(C17="",C17="No sé"),"",IF(AND(I17="Seguridad",MATCH(C17,Datos!$A$2:$A$6,0)>=2),"ALERTA DE SEGURIDAD",IF(AND(I17="Atención",MATCH(C17,Datos!$A$2:$A$6,0)>=4),"Atención",""))) | G17: =IF(OR(E17="",D17<=0),"",D17) | H17: =IF(G17="","",G17*E17) | K17: =IF(L10>0,"ALERTA: violencia, amenazas o control no se «compensan» con otros aspectos positivos, por eso no se da una lectura global. Si sentís miedo o estás en peligro, buscá ayuda de los servicios de emergencia o de organizaciones de apoyo a víctimas de violencia de tu país.","")
A18: Bueno | B18: Respeto | C18: No sé | D18: 1 | E18: =IF(OR(C18="",C18="No sé"),"",IF($A18="Bueno",(MATCH(C18,Datos!$A$2:$A$6,0)-1)*25,100-(MATCH(C18,Datos!$A$2:$A$6,0)-1)*25)) | F18: =IF(OR(C18="",C18="No sé"),"",IF(AND(I18="Seguridad",MATCH(C18,Datos!$A$2:$A$6,0)>=2),"ALERTA DE SEGURIDAD",IF(AND(I18="Atención",MATCH(C18,Datos!$A$2:$A$6,0)>=4),"Atención",""))) | G18: =IF(OR(E18="",D18<=0),"",D18) | H18: =IF(G18="","",G18*E18)
A19: Bueno | B19: Comunicativo | C19: No sé | D19: 1 | E19: =IF(OR(C19="",C19="No sé"),"",IF($A19="Bueno",(MATCH(C19,Datos!$A$2:$A$6,0)-1)*25,100-(MATCH(C19,Datos!$A$2:$A$6,0)-1)*25)) | F19: =IF(OR(C19="",C19="No sé"),"",IF(AND(I19="Seguridad",MATCH(C19,Datos!$A$2:$A$6,0)>=2),"ALERTA DE SEGURIDAD",IF(AND(I19="Atención",MATCH(C19,Datos!$A$2:$A$6,0)>=4),"Atención",""))) | G19: =IF(OR(E19="",D19<=0),"",D19) | H19: =IF(G19="","",G19*E19)
A20: Bueno | B20: Detallista | C20: No sé | D20: 1 | E20: =IF(OR(C20="",C20="No sé"),"",IF($A20="Bueno",(MATCH(C20,Datos!$A$2:$A$6,0)-1)*25,100-(MATCH(C20,Datos!$A$2:$A$6,0)-1)*25)) | F20: =IF(OR(C20="",C20="No sé"),"",IF(AND(I20="Seguridad",MATCH(C20,Datos!$A$2:$A$6,0)>=2),"ALERTA DE SEGURIDAD",IF(AND(I20="Atención",MATCH(C20,Datos!$A$2:$A$6,0)>=4),"Atención",""))) | G20: =IF(OR(E20="",D20<=0),"",D20) | H20: =IF(G20="","",G20*E20)
A21: Bueno | B21: Compartir juntos | C21: No sé | D21: 1 | E21: =IF(OR(C21="",C21="No sé"),"",IF($A21="Bueno",(MATCH(C21,Datos!$A$2:$A$6,0)-1)*25,100-(MATCH(C21,Datos!$A$2:$A$6,0)-1)*25)) | F21: =IF(OR(C21="",C21="No sé"),"",IF(AND(I21="Seguridad",MATCH(C21,Datos!$A$2:$A$6,0)>=2),"ALERTA DE SEGURIDAD",IF(AND(I21="Atención",MATCH(C21,Datos!$A$2:$A$6,0)>=4),"Atención",""))) | G21: =IF(OR(E21="",D21<=0),"",D21) | H21: =IF(G21="","",G21*E21)
A22: Bueno | B22: Cariñoso | C22: No sé | D22: 1 | E22: =IF(OR(C22="",C22="No sé"),"",IF($A22="Bueno",(MATCH(C22,Datos!$A$2:$A$6,0)-1)*25,100-(MATCH(C22,Datos!$A$2:$A$6,0)-1)*25)) | F22: =IF(OR(C22="",C22="No sé"),"",IF(AND(I22="Seguridad",MATCH(C22,Datos!$A$2:$A$6,0)>=2),"ALERTA DE SEGURIDAD",IF(AND(I22="Atención",MATCH(C22,Datos!$A$2:$A$6,0)>=4),"Atención",""))) | G22: =IF(OR(E22="",D22<=0),"",D22) | H22: =IF(G22="","",G22*E22) | K22: Cómo se calcula: cada casilla vale 0, 25, 50, 75 o 100 (en las filas «Malo» la escala está invertida: «Nada de eso» = 100). Los «No sé» no cuentan. Cada lista se promedia con sus pesos y el IRP es el promedio de ambas, siempre que haya al menos la mitad de cada lista respondida. Ver docs/irp.md.
A23: Bueno | B23: Estabilidad | C23: No sé | D23: 1 | E23: =IF(OR(C23="",C23="No sé"),"",IF($A23="Bueno",(MATCH(C23,Datos!$A$2:$A$6,0)-1)*25,100-(MATCH(C23,Datos!$A$2:$A$6,0)-1)*25)) | F23: =IF(OR(C23="",C23="No sé"),"",IF(AND(I23="Seguridad",MATCH(C23,Datos!$A$2:$A$6,0)>=2),"ALERTA DE SEGURIDAD",IF(AND(I23="Atención",MATCH(C23,Datos!$A$2:$A$6,0)>=4),"Atención",""))) | G23: =IF(OR(E23="",D23<=0),"",D23) | H23: =IF(G23="","",G23*E23)
A24: Bueno | B24: Compromiso | C24: No sé | D24: 1 | E24: =IF(OR(C24="",C24="No sé"),"",IF($A24="Bueno",(MATCH(C24,Datos!$A$2:$A$6,0)-1)*25,100-(MATCH(C24,Datos!$A$2:$A$6,0)-1)*25)) | F24: =IF(OR(C24="",C24="No sé"),"",IF(AND(I24="Seguridad",MATCH(C24,Datos!$A$2:$A$6,0)>=2),"ALERTA DE SEGURIDAD",IF(AND(I24="Atención",MATCH(C24,Datos!$A$2:$A$6,0)>=4),"Atención",""))) | G24: =IF(OR(E24="",D24<=0),"",D24) | H24: =IF(G24="","",G24*E24)
A25: Bueno | B25: Planes en conjunto | C25: No sé | D25: 1 | E25: =IF(OR(C25="",C25="No sé"),"",IF($A25="Bueno",(MATCH(C25,Datos!$A$2:$A$6,0)-1)*25,100-(MATCH(C25,Datos!$A$2:$A$6,0)-1)*25)) | F25: =IF(OR(C25="",C25="No sé"),"",IF(AND(I25="Seguridad",MATCH(C25,Datos!$A$2:$A$6,0)>=2),"ALERTA DE SEGURIDAD",IF(AND(I25="Atención",MATCH(C25,Datos!$A$2:$A$6,0)>=4),"Atención",""))) | G25: =IF(OR(E25="",D25<=0),"",D25) | H25: =IF(G25="","",G25*E25)
A26: Bueno | B26: Sin presumir (humildad) | C26: No sé | D26: 1 | E26: =IF(OR(C26="",C26="No sé"),"",IF($A26="Bueno",(MATCH(C26,Datos!$A$2:$A$6,0)-1)*25,100-(MATCH(C26,Datos!$A$2:$A$6,0)-1)*25)) | F26: =IF(OR(C26="",C26="No sé"),"",IF(AND(I26="Seguridad",MATCH(C26,Datos!$A$2:$A$6,0)>=2),"ALERTA DE SEGURIDAD",IF(AND(I26="Atención",MATCH(C26,Datos!$A$2:$A$6,0)>=4),"Atención",""))) | G26: =IF(OR(E26="",D26<=0),"",D26) | H26: =IF(G26="","",G26*E26)
A27: Bueno | B27: Gastos compartidos | C27: No sé | D27: 1 | E27: =IF(OR(C27="",C27="No sé"),"",IF($A27="Bueno",(MATCH(C27,Datos!$A$2:$A$6,0)-1)*25,100-(MATCH(C27,Datos!$A$2:$A$6,0)-1)*25)) | F27: =IF(OR(C27="",C27="No sé"),"",IF(AND(I27="Seguridad",MATCH(C27,Datos!$A$2:$A$6,0)>=2),"ALERTA DE SEGURIDAD",IF(AND(I27="Atención",MATCH(C27,Datos!$A$2:$A$6,0)>=4),"Atención",""))) | G27: =IF(OR(E27="",D27<=0),"",D27) | H27: =IF(G27="","",G27*E27)
A28: Bueno | B28: Responsable | C28: No sé | D28: 1 | E28: =IF(OR(C28="",C28="No sé"),"",IF($A28="Bueno",(MATCH(C28,Datos!$A$2:$A$6,0)-1)*25,100-(MATCH(C28,Datos!$A$2:$A$6,0)-1)*25)) | F28: =IF(OR(C28="",C28="No sé"),"",IF(AND(I28="Seguridad",MATCH(C28,Datos!$A$2:$A$6,0)>=2),"ALERTA DE SEGURIDAD",IF(AND(I28="Atención",MATCH(C28,Datos!$A$2:$A$6,0)>=4),"Atención",""))) | G28: =IF(OR(E28="",D28<=0),"",D28) | H28: =IF(G28="","",G28*E28)
A29: Bueno | B29: Buen sexo | C29: No sé | D29: 1 | E29: =IF(OR(C29="",C29="No sé"),"",IF($A29="Bueno",(MATCH(C29,Datos!$A$2:$A$6,0)-1)*25,100-(MATCH(C29,Datos!$A$2:$A$6,0)-1)*25)) | F29: =IF(OR(C29="",C29="No sé"),"",IF(AND(I29="Seguridad",MATCH(C29,Datos!$A$2:$A$6,0)>=2),"ALERTA DE SEGURIDAD",IF(AND(I29="Atención",MATCH(C29,Datos!$A$2:$A$6,0)>=4),"Atención",""))) | G29: =IF(OR(E29="",D29<=0),"",D29) | H29: =IF(G29="","",G29*E29)
A30: Bueno | B30: Confianza | C30: No sé | D30: 1 | E30: =IF(OR(C30="",C30="No sé"),"",IF($A30="Bueno",(MATCH(C30,Datos!$A$2:$A$6,0)-1)*25,100-(MATCH(C30,Datos!$A$2:$A$6,0)-1)*25)) | F30: =IF(OR(C30="",C30="No sé"),"",IF(AND(I30="Seguridad",MATCH(C30,Datos!$A$2:$A$6,0)>=2),"ALERTA DE SEGURIDAD",IF(AND(I30="Atención",MATCH(C30,Datos!$A$2:$A$6,0)>=4),"Atención",""))) | G30: =IF(OR(E30="",D30<=0),"",D30) | H30: =IF(G30="","",G30*E30)
A31: Malo | B31: Tristeza | C31: No sé | D31: 1 | E31: =IF(OR(C31="",C31="No sé"),"",IF($A31="Bueno",(MATCH(C31,Datos!$A$2:$A$6,0)-1)*25,100-(MATCH(C31,Datos!$A$2:$A$6,0)-1)*25)) | F31: =IF(OR(C31="",C31="No sé"),"",IF(AND(I31="Seguridad",MATCH(C31,Datos!$A$2:$A$6,0)>=2),"ALERTA DE SEGURIDAD",IF(AND(I31="Atención",MATCH(C31,Datos!$A$2:$A$6,0)>=4),"Atención",""))) | G31: =IF(OR(E31="",D31<=0),"",D31) | H31: =IF(G31="","",G31*E31)
A32: Malo | B32: Estrés | C32: No sé | D32: 1 | E32: =IF(OR(C32="",C32="No sé"),"",IF($A32="Bueno",(MATCH(C32,Datos!$A$2:$A$6,0)-1)*25,100-(MATCH(C32,Datos!$A$2:$A$6,0)-1)*25)) | F32: =IF(OR(C32="",C32="No sé"),"",IF(AND(I32="Seguridad",MATCH(C32,Datos!$A$2:$A$6,0)>=2),"ALERTA DE SEGURIDAD",IF(AND(I32="Atención",MATCH(C32,Datos!$A$2:$A$6,0)>=4),"Atención",""))) | G32: =IF(OR(E32="",D32<=0),"",D32) | H32: =IF(G32="","",G32*E32)
A33: Malo | B33: Inseguridad | C33: No sé | D33: 1 | E33: =IF(OR(C33="",C33="No sé"),"",IF($A33="Bueno",(MATCH(C33,Datos!$A$2:$A$6,0)-1)*25,100-(MATCH(C33,Datos!$A$2:$A$6,0)-1)*25)) | F33: =IF(OR(C33="",C33="No sé"),"",IF(AND(I33="Seguridad",MATCH(C33,Datos!$A$2:$A$6,0)>=2),"ALERTA DE SEGURIDAD",IF(AND(I33="Atención",MATCH(C33,Datos!$A$2:$A$6,0)>=4),"Atención",""))) | G33: =IF(OR(E33="",D33<=0),"",D33) | H33: =IF(G33="","",G33*E33)
A34: Malo | B34: Infidelidad | C34: No sé | D34: 1 | E34: =IF(OR(C34="",C34="No sé"),"",IF($A34="Bueno",(MATCH(C34,Datos!$A$2:$A$6,0)-1)*25,100-(MATCH(C34,Datos!$A$2:$A$6,0)-1)*25)) | F34: =IF(OR(C34="",C34="No sé"),"",IF(AND(I34="Seguridad",MATCH(C34,Datos!$A$2:$A$6,0)>=2),"ALERTA DE SEGURIDAD",IF(AND(I34="Atención",MATCH(C34,Datos!$A$2:$A$6,0)>=4),"Atención",""))) | G34: =IF(OR(E34="",D34<=0),"",D34) | H34: =IF(G34="","",G34*E34) | I34: Atención
A35: Malo | B35: Irrespeto | C35: No sé | D35: 1 | E35: =IF(OR(C35="",C35="No sé"),"",IF($A35="Bueno",(MATCH(C35,Datos!$A$2:$A$6,0)-1)*25,100-(MATCH(C35,Datos!$A$2:$A$6,0)-1)*25)) | F35: =IF(OR(C35="",C35="No sé"),"",IF(AND(I35="Seguridad",MATCH(C35,Datos!$A$2:$A$6,0)>=2),"ALERTA DE SEGURIDAD",IF(AND(I35="Atención",MATCH(C35,Datos!$A$2:$A$6,0)>=4),"Atención",""))) | G35: =IF(OR(E35="",D35<=0),"",D35) | H35: =IF(G35="","",G35*E35)
A36: Malo | B36: Fingir ser lo que no se es | C36: No sé | D36: 1 | E36: =IF(OR(C36="",C36="No sé"),"",IF($A36="Bueno",(MATCH(C36,Datos!$A$2:$A$6,0)-1)*25,100-(MATCH(C36,Datos!$A$2:$A$6,0)-1)*25)) | F36: =IF(OR(C36="",C36="No sé"),"",IF(AND(I36="Seguridad",MATCH(C36,Datos!$A$2:$A$6,0)>=2),"ALERTA DE SEGURIDAD",IF(AND(I36="Atención",MATCH(C36,Datos!$A$2:$A$6,0)>=4),"Atención",""))) | G36: =IF(OR(E36="",D36<=0),"",D36) | H36: =IF(G36="","",G36*E36)
A37: Malo | B37: Pegajoso | C37: No sé | D37: 1 | E37: =IF(OR(C37="",C37="No sé"),"",IF($A37="Bueno",(MATCH(C37,Datos!$A$2:$A$6,0)-1)*25,100-(MATCH(C37,Datos!$A$2:$A$6,0)-1)*25)) | F37: =IF(OR(C37="",C37="No sé"),"",IF(AND(I37="Seguridad",MATCH(C37,Datos!$A$2:$A$6,0)>=2),"ALERTA DE SEGURIDAD",IF(AND(I37="Atención",MATCH(C37,Datos!$A$2:$A$6,0)>=4),"Atención",""))) | G37: =IF(OR(E37="",D37<=0),"",D37) | H37: =IF(G37="","",G37*E37)
A38: Malo | B38: Falta de interés | C38: No sé | D38: 1 | E38: =IF(OR(C38="",C38="No sé"),"",IF($A38="Bueno",(MATCH(C38,Datos!$A$2:$A$6,0)-1)*25,100-(MATCH(C38,Datos!$A$2:$A$6,0)-1)*25)) | F38: =IF(OR(C38="",C38="No sé"),"",IF(AND(I38="Seguridad",MATCH(C38,Datos!$A$2:$A$6,0)>=2),"ALERTA DE SEGURIDAD",IF(AND(I38="Atención",MATCH(C38,Datos!$A$2:$A$6,0)>=4),"Atención",""))) | G38: =IF(OR(E38="",D38<=0),"",D38) | H38: =IF(G38="","",G38*E38)
A39: Malo | B39: No te ayuda | C39: No sé | D39: 1 | E39: =IF(OR(C39="",C39="No sé"),"",IF($A39="Bueno",(MATCH(C39,Datos!$A$2:$A$6,0)-1)*25,100-(MATCH(C39,Datos!$A$2:$A$6,0)-1)*25)) | F39: =IF(OR(C39="",C39="No sé"),"",IF(AND(I39="Seguridad",MATCH(C39,Datos!$A$2:$A$6,0)>=2),"ALERTA DE SEGURIDAD",IF(AND(I39="Atención",MATCH(C39,Datos!$A$2:$A$6,0)>=4),"Atención",""))) | G39: =IF(OR(E39="",D39<=0),"",D39) | H39: =IF(G39="","",G39*E39)
A40: Malo | B40: Ser egoísta | C40: No sé | D40: 1 | E40: =IF(OR(C40="",C40="No sé"),"",IF($A40="Bueno",(MATCH(C40,Datos!$A$2:$A$6,0)-1)*25,100-(MATCH(C40,Datos!$A$2:$A$6,0)-1)*25)) | F40: =IF(OR(C40="",C40="No sé"),"",IF(AND(I40="Seguridad",MATCH(C40,Datos!$A$2:$A$6,0)>=2),"ALERTA DE SEGURIDAD",IF(AND(I40="Atención",MATCH(C40,Datos!$A$2:$A$6,0)>=4),"Atención",""))) | G40: =IF(OR(E40="",D40<=0),"",D40) | H40: =IF(G40="","",G40*E40)
A41: Malo | B41: Sin metas claras | C41: No sé | D41: 1 | E41: =IF(OR(C41="",C41="No sé"),"",IF($A41="Bueno",(MATCH(C41,Datos!$A$2:$A$6,0)-1)*25,100-(MATCH(C41,Datos!$A$2:$A$6,0)-1)*25)) | F41: =IF(OR(C41="",C41="No sé"),"",IF(AND(I41="Seguridad",MATCH(C41,Datos!$A$2:$A$6,0)>=2),"ALERTA DE SEGURIDAD",IF(AND(I41="Atención",MATCH(C41,Datos!$A$2:$A$6,0)>=4),"Atención",""))) | G41: =IF(OR(E41="",D41<=0),"",D41) | H41: =IF(G41="","",G41*E41)
...

Sheet Léeme
A1: IRP mejorado — cómo usarlo
A2: 1. En la hoja IRP elegí una respuesta para cada casilla (columna C, celdas amarillas). «No sé» deja la casilla fuera del cálculo.
A3: 2. Si querés darle más o menos importancia a una casilla, cambiá su peso (columna D, por defecto 1; 0 la excluye).
A4: 3. Mirá el resultado a la derecha (columnas K y L). Con una alerta de seguridad no se da lectura global.
A6: Qué cambió respecto del Excel original
A7: • Escala real de 0 a 100 (el original iba de 20 a 100).
A8: • Suman las 51 casillas (el original dejaba 3 sin sumar: Comunicativo, Detallista y Siempre tiene la razón).
A9: • Existe «No sé» y se informa la cobertura.
A10: • Alertas de seguridad para violencia, amenazas y control; la lectura global no se da en ese caso.
A11: • Lectura descriptiva y neutral, sin órdenes ni juicios sobre la persona.
A12: • Corregida la etiqueta invertida de «Presumir».
A14: Límites
... A16: Basado en la hoja «Índice de Relación de Pareja» de standleymoise (2021). Código MIT / documentación CC BY 4.0: https://github.com/standleymoise/relationship-choice-model

Sheet Datos
A1: Respuesta | B1: Posición (0–4)
A2: Nada de eso | B2: 0
A3: Muy poco | B3: 1
A4: Poco | B4: 2
A5: Normal | B5: 3
A6: Mucho | B6: 4
A7: No sé
